2022-02-06 11:44:52 info: ---------------------------------------
2022-02-06 11:44:52 info: >>> Running Unit Test `ex1-johnWho` <<<
2022-02-06 11:44:52 info: ---------------------------------------
2022-02-06 11:44:55 error: *** Unit Test Error Report ***

Command failed: npx jest ex1-johnWho.test.js --colors
 FAIL  3-UsingAPIs/Week1/unit-tests/ex1-johnWho.test.js
  getAnonName
    ✓ should exist and be executable (1 ms)
    ✕ should have all TODO comments removed (1 ms)
    ✓ `getAnonName` should not contain unneeded console.log calls
    ✓ should call `new Promise()`
    ✓ should take a single argument
    ✓ `resolve()` should be called with a one argument
    ✓ `reject()` should be called with a one argument
    ✓ should resolve when called with a string argument
    ✓ should reject with an Error object when called without an argument

  ● getAnonName › should have all TODO comments removed

    expect(received).toBeFalsy()

    Received: true

      103 | function testTodosRemoved(getSource) {
      104 |   test('should have all TODO comments removed', () => {
    > 105 |     expect(/\bTODO\b/.test(getSource())).toBeFalsy();
          |                                          ^
      106 |   });
      107 | }
      108 |

      at Object.<anonymous> (test-runner/unit-test-helpers.js:105:42)

Test Suites: 1 failed, 1 total
Tests:       1 failed, 8 passed, 9 total
Snapshots:   0 total
Time:        0.229 s
Ran all test suites matching /ex1-johnWho.test.js/i.

  ●  Cannot log after tests are done. Did you forget to wait for something async in your test?
    Attempted to log "John Doe".

      25 |
      26 |
    > 27 |   getAnonName('John').then((data)=>console.log(data));
         |                                          ^
      28 |
      29 |
      30 |

      at console.log (node_modules/@jest/console/build/CustomConsole.js:187:10)
      at 3-UsingAPIs/Week1/homework/ex1-johnWho.js:27:42
2022-02-06 11:44:55 error: *** ESLint Report ***

ex1-johnWho.js
  33:3  error  'main' is not defined  no-undef

✖ 1 problem (1 error, 0 warnings)


2022-02-06 11:47:06 info: ---------------------------------------
2022-02-06 11:47:06 info: >>> Running Unit Test `ex1-johnWho` <<<
2022-02-06 11:47:06 info: ---------------------------------------
2022-02-06 11:47:08 error: *** Unit Test Error Report ***

Command failed: npx jest ex1-johnWho.test.js --colors
 FAIL  3-UsingAPIs/Week1/unit-tests/ex1-johnWho.test.js
  getAnonName
    ✓ should exist and be executable
    ✕ should have all TODO comments removed
    ✓ `getAnonName` should not contain unneeded console.log calls
    ✓ should call `new Promise()`
    ✓ should take a single argument
    ✓ `resolve()` should be called with a one argument
    ✓ `reject()` should be called with a one argument
    ✓ should resolve when called with a string argument (1 ms)
    ✓ should reject with an Error object when called without an argument

  ● getAnonName › should have all TODO comments removed

    expect(received).toBeFalsy()

    Received: true

      103 | function testTodosRemoved(getSource) {
      104 |   test('should have all TODO comments removed', () => {
    > 105 |     expect(/\bTODO\b/.test(getSource())).toBeFalsy();
          |                                          ^
      106 |   });
      107 | }
      108 |

      at Object.<anonymous> (test-runner/unit-test-helpers.js:105:42)

Test Suites: 1 failed, 1 total
Tests:       1 failed, 8 passed, 9 total
Snapshots:   0 total
Time:        0.188 s, estimated 1 s
Ran all test suites matching /ex1-johnWho.test.js/i.

  ●  Cannot log after tests are done. Did you forget to wait for something async in your test?
    Attempted to log "John Doe".

      25 |
      26 | getAnonName('John').then((data) => console.log(data));
    > 27 |
         | ^
      28 | // ! Do not change or remove the code below
      29 | if (process.env.NODE_ENV !== 'test') {
      30 |   main();

      at console.log (node_modules/@jest/console/build/CustomConsole.js:187:10)
      at 3-UsingAPIs/Week1/homework/ex1-johnWho.js:27:42
2022-02-06 11:47:09 error: *** ESLint Report ***

ex1-johnWho.js
  30:3  error  'main' is not defined  no-undef

✖ 1 problem (1 error, 0 warnings)


2022-02-06 11:49:14 info: ---------------------------------------
2022-02-06 11:49:14 info: >>> Running Unit Test `ex1-johnWho` <<<
2022-02-06 11:49:14 info: ---------------------------------------
2022-02-06 11:49:15 error: *** Unit Test Error Report ***

Command failed: npx jest ex1-johnWho.test.js --colors
 FAIL  3-UsingAPIs/Week1/unit-tests/ex1-johnWho.test.js
  getAnonName
    ✓ should exist and be executable
    ✕ should have all TODO comments removed
    ✓ `getAnonName` should not contain unneeded console.log calls
    ✓ should call `new Promise()` (1 ms)
    ✓ should take a single argument
    ✓ `resolve()` should be called with a one argument
    ✓ `reject()` should be called with a one argument
    ✓ should resolve when called with a string argument (1 ms)
    ✓ should reject with an Error object when called without an argument

  ● getAnonName › should have all TODO comments removed

    expect(received).toBeFalsy()

    Received: true

      103 | function testTodosRemoved(getSource) {
      104 |   test('should have all TODO comments removed', () => {
    > 105 |     expect(/\bTODO\b/.test(getSource())).toBeFalsy();
          |                                          ^
      106 |   });
      107 | }
      108 |

      at Object.<anonymous> (test-runner/unit-test-helpers.js:105:42)

Test Suites: 1 failed, 1 total
Tests:       1 failed, 8 passed, 9 total
Snapshots:   0 total
Time:        0.188 s, estimated 1 s
Ran all test suites matching /ex1-johnWho.test.js/i.
2022-02-06 11:50:06 info: ---------------------------------------
2022-02-06 11:50:06 info: >>> Running Unit Test `ex1-johnWho` <<<
2022-02-06 11:50:06 info: ---------------------------------------
2022-02-06 11:50:07 error: *** Unit Test Error Report ***

Command failed: npx jest ex1-johnWho.test.js --colors
 FAIL  3-UsingAPIs/Week1/unit-tests/ex1-johnWho.test.js
  getAnonName
    ✓ should exist and be executable
    ✕ should have all TODO comments removed
    ✓ `getAnonName` should not contain unneeded console.log calls
    ✓ should call `new Promise()` (1 ms)
    ✓ should take a single argument
    ✓ `resolve()` should be called with a one argument
    ✓ `reject()` should be called with a one argument
    ✓ should resolve when called with a string argument (1 ms)
    ✓ should reject with an Error object when called without an argument

  ● getAnonName › should have all TODO comments removed

    expect(received).toBeFalsy()

    Received: true

      103 | function testTodosRemoved(getSource) {
      104 |   test('should have all TODO comments removed', () => {
    > 105 |     expect(/\bTODO\b/.test(getSource())).toBeFalsy();
          |                                          ^
      106 |   });
      107 | }
      108 |

      at Object.<anonymous> (test-runner/unit-test-helpers.js:105:42)

Test Suites: 1 failed, 1 total
Tests:       1 failed, 8 passed, 9 total
Snapshots:   0 total
Time:        0.189 s, estimated 1 s
Ran all test suites matching /ex1-johnWho.test.js/i.
2022-02-06 11:50:44 info: ---------------------------------------
2022-02-06 11:50:44 info: >>> Running Unit Test `ex1-johnWho` <<<
2022-02-06 11:50:44 info: ---------------------------------------
2022-02-06 11:50:45 info: All unit tests passed.
2022-02-06 11:50:46 info: All steps were completed successfully
2022-02-07 12:01:42 info: -------------------------------------------------
2022-02-07 12:01:42 info: >>> Running Unit Test `ex2-checkDoubleDigits` <<<
2022-02-07 12:01:42 info: -------------------------------------------------
2022-02-07 12:01:43 error: *** Unit Test Error Report ***

Command failed: npx jest ex2-checkDoubleDigits.test.js --colors
 FAIL  3-UsingAPIs/Week1/unit-tests/ex2-checkDoubleDigits.test.js
  checkDoubleDigits
    ✓ should exist and be executable
    ✓ should have all TODO comments removed
    ✓ `checkDoubleDigits` should not contain unneeded console.log calls
    ✓ should call new Promise()
    ✓ `resolve()` should be called with a one argument
    ✓ `reject()` should be called with a one argument
    ✓ should be a function that takes a single argument
    ✕ (9) should return a rejected promise with an Error object (1 ms)
    ✕ (10) should return a promise that resolves to "This is a double digit number!"
    ✓ (99) should return a promise that resolves to "This is a double digit number!"
    ✕ (100) should return a rejected promise with an Error object

  ● checkDoubleDigits › (9) should return a rejected promise with an Error object

    expect(received).rejects.toBeInstanceOf(expected)

    Expected constructor: Error

    Received value has no prototype
    Received value: "Expected a double digit number but got 9"

      65 |     const promise = checkDoubleDigits(9);
      66 |     expect(promise).toBeInstanceOf(Promise);
    > 67 |     return expect(promise).rejects.toBeInstanceOf(Error);
         |                                    ^
      68 |   });
      69 |
      70 |   test('(10) should return a promise that resolves to "This is a double digit number!"', () => {

      at Object.toBeInstanceOf (node_modules/expect/build/index.js:285:22)
      at Object.<anonymous> (3-UsingAPIs/Week1/unit-tests/ex2-checkDoubleDigits.test.js:67:36)

  ● checkDoubleDigits › (10) should return a promise that resolves to "This is a double digit number!"

    expect(received).resolves.toEqual()

    Received promise rejected instead of resolved
    Rejected to value: "Expected a double digit number but got 10"

      73 |     const promise = checkDoubleDigits(10);
      74 |     expect(promise).toBeInstanceOf(Promise);
    > 75 |     return expect(promise).resolves.toEqual(
         |            ^
      76 |       expect.stringContaining('This is a double digit number!')
      77 |     );
      78 |   });

      at expect (node_modules/expect/build/index.js:178:15)
      at Object.<anonymous> (3-UsingAPIs/Week1/unit-tests/ex2-checkDoubleDigits.test.js:75:12)

  ● checkDoubleDigits › (10) should return a promise that resolves to "This is a double digit number!"

    expect.assertions(3)

    Expected three assertions to be called but received two assertion calls.

      69 |
      70 |   test('(10) should return a promise that resolves to "This is a double digit number!"', () => {
    > 71 |     expect.assertions(3);
         |            ^
      72 |     expect(exported).toBeDefined();
      73 |     const promise = checkDoubleDigits(10);
      74 |     expect(promise).toBeInstanceOf(Promise);

      at Object.<anonymous> (3-UsingAPIs/Week1/unit-tests/ex2-checkDoubleDigits.test.js:71:12)

  ● checkDoubleDigits › (100) should return a rejected promise with an Error object

    expect(received).rejects.toBeInstanceOf(expected)

    Expected constructor: Error

    Received value has no prototype
    Received value: "Expected a double digit number but got 100"

      91 |     const promise = checkDoubleDigits(100);
      92 |     expect(promise).toBeInstanceOf(Promise);
    > 93 |     return expect(promise).rejects.toBeInstanceOf(Error);
         |                                    ^
      94 |   });
      95 | });
      96 |

      at Object.toBeInstanceOf (node_modules/expect/build/index.js:285:22)
      at Object.<anonymous> (3-UsingAPIs/Week1/unit-tests/ex2-checkDoubleDigits.test.js:93:36)

Test Suites: 1 failed, 1 total
Tests:       3 failed, 8 passed, 11 total
Snapshots:   0 total
Time:        0.218 s
Ran all test suites matching /ex2-checkDoubleDigits.test.js/i.
2022-02-07 12:03:33 info: -------------------------------------------------
2022-02-07 12:03:33 info: >>> Running Unit Test `ex2-checkDoubleDigits` <<<
2022-02-07 12:03:33 info: -------------------------------------------------
2022-02-07 12:03:34 info: All unit tests passed.
2022-02-07 12:03:36 info: All steps were completed successfully
2022-02-07 12:04:43 info: -------------------------------------------------
2022-02-07 12:04:43 info: >>> Running Unit Test `ex2-checkDoubleDigits` <<<
2022-02-07 12:04:43 info: -------------------------------------------------
2022-02-07 12:04:44 info: All unit tests passed.
2022-02-07 12:04:45 info: All steps were completed successfully
2022-02-07 12:16:32 info: ---------------------------------------
2022-02-07 12:16:32 info: >>> Running Unit Test `ex3-rollDie` <<<
2022-02-07 12:16:32 info: ---------------------------------------
2022-02-07 12:16:35 error: *** Unit Test Error Report ***

Command failed: npx jest ex3-rollDie.test.js --colors
 PASS  3-UsingAPIs/Week1/unit-tests/ex3-rollDie.test.js
  rollDie
    ✓ should exist and be executable (1 ms)
    ✓ should have all TODO comments removed
    ✓ should call `new Promise()` (1 ms)
    ✓ `resolve()` should be called with a one argument
    ✓ `reject()` should be called with a one argument
    ✓ should resolve when the die settles successfully
    ✓ should reject with an Error when the die rolls off the table (1 ms)

Test Suites: 1 passed, 1 total
Tests:       7 passed, 7 total
Snapshots:   0 total
Time:        0.2 s
Ran all test suites matching /ex3-rollDie.test.js/i.

  ●  Cannot log after tests are done. Did you forget to wait for something async in your test?
    Attempted to log "Die value is now: 4".

      23 |       console.log(`Die value is now: ${value}`);
      24 |
    > 25 |       // Use callback to notify that the die rolled off the table after 6 rolls
         |               ^
      26 |
      27 |       if (roll > 6) {
      28 |         reject(new Error('Oops... Die rolled off the table.'));

      at console.log (node_modules/@jest/console/build/CustomConsole.js:187:10)
      at rollOnce (3-UsingAPIs/Week1/homework/ex3-rollDie.js:25:15)
      at Timeout._onTimeout (3-UsingAPIs/Week1/homework/ex3-rollDie.js:34:38)

Jest did not exit one second after the test run has completed.

This usually means that there are asynchronous operations that weren't stopped in your tests. Consider running Jest with `--detectOpenHandles` to troubleshoot this issue.

  ●  Cannot log after tests are done. Did you forget to wait for something async in your test?
    Attempted to log "Die value is now: 6".

      23 |       console.log(`Die value is now: ${value}`);
      24 |
    > 25 |       // Use callback to notify that the die rolled off the table after 6 rolls
         |               ^
      26 |
      27 |       if (roll > 6) {
      28 |         reject(new Error('Oops... Die rolled off the table.'));

      at console.log (node_modules/@jest/console/build/CustomConsole.js:187:10)
      at rollOnce (3-UsingAPIs/Week1/homework/ex3-rollDie.js:25:15)
      at Timeout._onTimeout (3-UsingAPIs/Week1/homework/ex3-rollDie.js:34:38)


  ●  Cannot log after tests are done. Did you forget to wait for something async in your test?
    Attempted to log "Success! Die settled on 6.".

      42 |
      43 | function main() {
    > 44 |   rollDie()
         |            ^
      45 |     .then((value) => console.log(`Success! Die settled on ${value}.`))
      46 |     .catch((error) => {
      47 |       clearTimeout(timeoutID);

      at console.log (node_modules/@jest/console/build/CustomConsole.js:187:10)
      at 3-UsingAPIs/Week1/homework/ex3-rollDie.js:44:35
2022-02-07 12:18:45 info: ---------------------------------------
2022-02-07 12:18:45 info: >>> Running Unit Test `ex3-rollDie` <<<
2022-02-07 12:18:45 info: ---------------------------------------
2022-02-07 12:18:49 error: *** Unit Test Error Report ***

Command failed: npx jest ex3-rollDie.test.js --colors
 PASS  3-UsingAPIs/Week1/unit-tests/ex3-rollDie.test.js
  rollDie
    ✓ should exist and be executable (1 ms)
    ✓ should have all TODO comments removed
    ✓ should call `new Promise()`
    ✓ `resolve()` should be called with a one argument
    ✓ `reject()` should be called with a one argument
    ✓ should resolve when the die settles successfully (1 ms)
    ✓ should reject with an Error when the die rolls off the table

Test Suites: 1 passed, 1 total
Tests:       7 passed, 7 total
Snapshots:   0 total
Time:        0.18 s, estimated 1 s
Ran all test suites matching /ex3-rollDie.test.js/i.

  ●  Cannot log after tests are done. Did you forget to wait for something async in your test?
    Attempted to log "Die value is now: 2".

      23 |       console.log(`Die value is now: ${value}`);
      24 |
    > 25 |       // Use callback to notify that the die rolled off the table after 6 rolls
         |               ^
      26 |
      27 |       if (roll >= 6) {
      28 |         reject(new Error('Oops... Die rolled off the table.'));

      at console.log (node_modules/@jest/console/build/CustomConsole.js:187:10)
      at rollOnce (3-UsingAPIs/Week1/homework/ex3-rollDie.js:25:15)
      at Timeout._onTimeout (3-UsingAPIs/Week1/homework/ex3-rollDie.js:34:38)

Jest did not exit one second after the test run has completed.

This usually means that there are asynchronous operations that weren't stopped in your tests. Consider running Jest with `--detectOpenHandles` to troubleshoot this issue.

  ●  Cannot log after tests are done. Did you forget to wait for something async in your test?
    Attempted to log "Die value is now: 2".

      23 |       console.log(`Die value is now: ${value}`);
      24 |
    > 25 |       // Use callback to notify that the die rolled off the table after 6 rolls
         |               ^
      26 |
      27 |       if (roll >= 6) {
      28 |         reject(new Error('Oops... Die rolled off the table.'));

      at console.log (node_modules/@jest/console/build/CustomConsole.js:187:10)
      at rollOnce (3-UsingAPIs/Week1/homework/ex3-rollDie.js:25:15)
      at Timeout._onTimeout (3-UsingAPIs/Week1/homework/ex3-rollDie.js:34:38)


  ●  Cannot log after tests are done. Did you forget to wait for something async in your test?
    Attempted to log "Die value is now: 6".

      23 |       console.log(`Die value is now: ${value}`);
      24 |
    > 25 |       // Use callback to notify that the die rolled off the table after 6 rolls
         |               ^
      26 |
      27 |       if (roll >= 6) {
      28 |         reject(new Error('Oops... Die rolled off the table.'));

      at console.log (node_modules/@jest/console/build/CustomConsole.js:187:10)
      at rollOnce (3-UsingAPIs/Week1/homework/ex3-rollDie.js:25:15)
      at Timeout._onTimeout (3-UsingAPIs/Week1/homework/ex3-rollDie.js:34:38)


  ●  Cannot log after tests are done. Did you forget to wait for something async in your test?
    Attempted to log "Die value is now: 1".

      23 |       console.log(`Die value is now: ${value}`);
      24 |
    > 25 |       // Use callback to notify that the die rolled off the table after 6 rolls
         |               ^
      26 |
      27 |       if (roll >= 6) {
      28 |         reject(new Error('Oops... Die rolled off the table.'));

      at console.log (node_modules/@jest/console/build/CustomConsole.js:187:10)
      at rollOnce (3-UsingAPIs/Week1/homework/ex3-rollDie.js:25:15)
      at Timeout._onTimeout (3-UsingAPIs/Week1/homework/ex3-rollDie.js:34:38)


  ●  Cannot log after tests are done. Did you forget to wait for something async in your test?
    Attempted to log "Die value is now: 2".

      23 |       console.log(`Die value is now: ${value}`);
      24 |
    > 25 |       // Use callback to notify that the die rolled off the table after 6 rolls
         |               ^
      26 |
      27 |       if (roll >= 6) {
      28 |         reject(new Error('Oops... Die rolled off the table.'));

      at console.log (node_modules/@jest/console/build/CustomConsole.js:187:10)
      at rollOnce (3-UsingAPIs/Week1/homework/ex3-rollDie.js:25:15)
      at Timeout._onTimeout (3-UsingAPIs/Week1/homework/ex3-rollDie.js:34:38)


  ●  Cannot log after tests are done. Did you forget to wait for something async in your test?
    Attempted to log "Oops... Die rolled off the table.".

      44 |   rollDie()
      45 |     .then((value) => console.log(`Success! Die settled on ${value}.`))
    > 46 |     .catch((error) => {
         |             ^
      47 |       clearTimeout(timeoutID);
      48 |       console.log(error.message);
      49 |     });

      at console.log (node_modules/@jest/console/build/CustomConsole.js:187:10)
      at 3-UsingAPIs/Week1/homework/ex3-rollDie.js:46:13
2022-02-07 12:23:40 info: ---------------------------------------
2022-02-07 12:23:40 info: >>> Running Unit Test `ex3-rollDie` <<<
2022-02-07 12:23:40 info: ---------------------------------------
2022-02-07 12:23:44 error: *** Unit Test Error Report ***

Command failed: npx jest ex3-rollDie.test.js --colors
 PASS  3-UsingAPIs/Week1/unit-tests/ex3-rollDie.test.js
  rollDie
    ✓ should exist and be executable (1 ms)
    ✓ should have all TODO comments removed (1 ms)
    ✓ should call `new Promise()`
    ✓ `resolve()` should be called with a one argument
    ✓ `reject()` should be called with a one argument
    ✓ should resolve when the die settles successfully (1 ms)
    ✓ should reject with an Error when the die rolls off the table

Test Suites: 1 passed, 1 total
Tests:       7 passed, 7 total
Snapshots:   0 total
Time:        0.207 s, estimated 1 s
Ran all test suites matching /ex3-rollDie.test.js/i.

  ●  Cannot log after tests are done. Did you forget to wait for something async in your test?
    Attempted to log "Die value is now: 6".

      21 |       const value = Math.floor(Math.random() * 6) + 1;
      22 |       console.log(`Die value is now: ${value}`);
    > 23 |
         | ^
      24 |       // Use callback to notify that the die rolled off the table after 6 rolls
      25 |
      26 |       if (roll > 6) {

      at console.log (node_modules/@jest/console/build/CustomConsole.js:187:10)
      at rollOnce (3-UsingAPIs/Week1/homework/ex3-rollDie.js:23:15)
      at Timeout._onTimeout (3-UsingAPIs/Week1/homework/ex3-rollDie.js:32:26)

Jest did not exit one second after the test run has completed.

This usually means that there are asynchronous operations that weren't stopped in your tests. Consider running Jest with `--detectOpenHandles` to troubleshoot this issue.

  ●  Cannot log after tests are done. Did you forget to wait for something async in your test?
    Attempted to log "Die value is now: 1".

      21 |       const value = Math.floor(Math.random() * 6) + 1;
      22 |       console.log(`Die value is now: ${value}`);
    > 23 |
         | ^
      24 |       // Use callback to notify that the die rolled off the table after 6 rolls
      25 |
      26 |       if (roll > 6) {

      at console.log (node_modules/@jest/console/build/CustomConsole.js:187:10)
      at rollOnce (3-UsingAPIs/Week1/homework/ex3-rollDie.js:23:15)
      at Timeout._onTimeout (3-UsingAPIs/Week1/homework/ex3-rollDie.js:32:26)


  ●  Cannot log after tests are done. Did you forget to wait for something async in your test?
    Attempted to log "Die value is now: 1".

      21 |       const value = Math.floor(Math.random() * 6) + 1;
      22 |       console.log(`Die value is now: ${value}`);
    > 23 |
         | ^
      24 |       // Use callback to notify that the die rolled off the table after 6 rolls
      25 |
      26 |       if (roll > 6) {

      at console.log (node_modules/@jest/console/build/CustomConsole.js:187:10)
      at rollOnce (3-UsingAPIs/Week1/homework/ex3-rollDie.js:23:15)
      at Timeout._onTimeout (3-UsingAPIs/Week1/homework/ex3-rollDie.js:32:26)


  ●  Cannot log after tests are done. Did you forget to wait for something async in your test?
    Attempted to log "Die value is now: 2".

      21 |       const value = Math.floor(Math.random() * 6) + 1;
      22 |       console.log(`Die value is now: ${value}`);
    > 23 |
         | ^
      24 |       // Use callback to notify that the die rolled off the table after 6 rolls
      25 |
      26 |       if (roll > 6) {

      at console.log (node_modules/@jest/console/build/CustomConsole.js:187:10)
      at rollOnce (3-UsingAPIs/Week1/homework/ex3-rollDie.js:23:15)
      at Timeout._onTimeout (3-UsingAPIs/Week1/homework/ex3-rollDie.js:32:26)


  ●  Cannot log after tests are done. Did you forget to wait for something async in your test?
    Attempted to log "Die value is now: 3".

      21 |       const value = Math.floor(Math.random() * 6) + 1;
      22 |       console.log(`Die value is now: ${value}`);
    > 23 |
         | ^
      24 |       // Use callback to notify that the die rolled off the table after 6 rolls
      25 |
      26 |       if (roll > 6) {

      at console.log (node_modules/@jest/console/build/CustomConsole.js:187:10)
      at rollOnce (3-UsingAPIs/Week1/homework/ex3-rollDie.js:23:15)
      at Timeout._onTimeout (3-UsingAPIs/Week1/homework/ex3-rollDie.js:32:26)


  ●  Cannot log after tests are done. Did you forget to wait for something async in your test?
    Attempted to log "Die value is now: 1".

      21 |       const value = Math.floor(Math.random() * 6) + 1;
      22 |       console.log(`Die value is now: ${value}`);
    > 23 |
         | ^
      24 |       // Use callback to notify that the die rolled off the table after 6 rolls
      25 |
      26 |       if (roll > 6) {

      at console.log (node_modules/@jest/console/build/CustomConsole.js:187:10)
      at rollOnce (3-UsingAPIs/Week1/homework/ex3-rollDie.js:23:15)
      at Timeout._onTimeout (3-UsingAPIs/Week1/homework/ex3-rollDie.js:32:26)


  ●  Cannot log after tests are done. Did you forget to wait for something async in your test?
    Attempted to log "Oops... Die rolled off the table.".

      41 |
      42 | function main() {
    > 43 |   rollDie()
         |            ^
      44 |     .then((value) => console.log(`Success! Die settled on ${value}.`))
      45 |     .catch((error) => {
      46 |       console.log(error.message);

      at console.log (node_modules/@jest/console/build/CustomConsole.js:187:10)
      at 3-UsingAPIs/Week1/homework/ex3-rollDie.js:43:13
2022-02-07 12:25:04 info: ---------------------------------------
2022-02-07 12:25:04 info: >>> Running Unit Test `ex3-rollDie` <<<
2022-02-07 12:25:04 info: ---------------------------------------
2022-02-07 12:25:05 info: All unit tests passed.
2022-02-07 12:25:06 info: All steps were completed successfully
2022-02-07 12:25:57 info: ---------------------------------------
2022-02-07 12:25:57 info: >>> Running Unit Test `ex3-rollDie` <<<
2022-02-07 12:25:57 info: ---------------------------------------
2022-02-07 12:25:58 info: All unit tests passed.
2022-02-07 12:25:59 info: All steps were completed successfully
2022-02-07 12:26:36 info: ---------------------------------------
2022-02-07 12:26:36 info: >>> Running Unit Test `ex3-rollDie` <<<
2022-02-07 12:26:36 info: ---------------------------------------
2022-02-07 12:26:37 info: All unit tests passed.
2022-02-07 12:26:38 info: All steps were completed successfully
2022-02-07 02:30:01 info: --------------------------------------------
2022-02-07 02:30:01 info: >>> Running Unit Test `ex4-pokerDiceAll` <<<
2022-02-07 02:30:01 info: --------------------------------------------
2022-02-07 02:30:02 error: *** Unit Test Error Report ***

Command failed: npx jest ex4-pokerDiceAll.test.js --colors
node:internal/process/promises:246
          triggerUncaughtException(err, true /* fromPromise */);
          ^

[UnhandledPromiseRejection: This error originated either by throwing inside of an async function without a catch block, or by rejecting a promise which was not handled with .catch(). The promise rejected with the reason "Error: Die 1 rolled off the table.
".] {
  code: 'ERR_UNHANDLED_REJECTION'
}
2022-02-07 02:30:29 info: --------------------------------------------
2022-02-07 02:30:29 info: >>> Running Unit Test `ex4-pokerDiceAll` <<<
2022-02-07 02:30:29 info: --------------------------------------------
2022-02-07 02:30:30 error: *** Unit Test Error Report ***

Command failed: npx jest ex4-pokerDiceAll.test.js --colors
node:internal/process/promises:246
          triggerUncaughtException(err, true /* fromPromise */);
          ^

[UnhandledPromiseRejection: This error originated either by throwing inside of an async function without a catch block, or by rejecting a promise which was not handled with .catch(). The promise rejected with the reason "Error: Die 1 rolled off the table.
".] {
  code: 'ERR_UNHANDLED_REJECTION'
}
2022-02-07 02:30:30 error: *** ESLint Report ***

ex4-pokerDiceAll.js
  23:1  warning  Remove commented-out code  hyf/no-commented-out-code

✖ 1 problem (0 errors, 1 warning)


2022-02-07 02:45:35 info: --------------------------------------------
2022-02-07 02:45:35 info: >>> Running Unit Test `ex4-pokerDiceAll` <<<
2022-02-07 02:45:35 info: --------------------------------------------
2022-02-07 02:45:36 error: *** Unit Test Error Report ***

Command failed: npx jest ex4-pokerDiceAll.test.js --colors
 FAIL  3-UsingAPIs/Week1/unit-tests/ex4-pokerDiceAll.test.js
  ex4-pokerDiceAll
    ✓ should exist and be executable
    ✓ should have all TODO comments removed
    ✕ `rollDice` should not contain unneeded console.log calls (1 ms)
    ✓ should use `dice.map()`
    ✓ should use `Promise.all()`
    ✓ should resolve when all dice settle successfully (4 ms)
    ✓ should reject with an Error when a die rolls off the table (27 ms)

  ● ex4-pokerDiceAll › `rollDice` should not contain unneeded console.log calls

    expect(received).toBe(expected) // Object.is equality

    Expected: false
    Received: true

      137 |       });
      138 |
    > 139 |     expect(callsConsoleLog).toBe(false);
          |                             ^
      140 |   });
      141 | }
      142 |

      at Object.<anonymous> (test-runner/unit-test-helpers.js:139:29)

Test Suites: 1 failed, 1 total
Tests:       1 failed, 6 passed, 7 total
Snapshots:   0 total
Time:        0.229 s
Ran all test suites matching /ex4-pokerDiceAll.test.js/i.
2022-02-07 02:47:08 info: --------------------------------------------
2022-02-07 02:47:08 info: >>> Running Unit Test `ex4-pokerDiceAll` <<<
2022-02-07 02:47:08 info: --------------------------------------------
2022-02-07 02:47:10 error: *** Unit Test Error Report ***

Command failed: npx jest ex4-pokerDiceAll.test.js --colors
 FAIL  3-UsingAPIs/Week1/unit-tests/ex4-pokerDiceAll.test.js
  ex4-pokerDiceAll
    ✓ should exist and be executable (1 ms)
    ✓ should have all TODO comments removed
    ✕ `rollDice` should not contain unneeded console.log calls (2 ms)
    ✓ should use `dice.map()`
    ✓ should use `Promise.all()`
    ✓ should resolve when all dice settle successfully (4 ms)
    ✓ should reject with an Error when a die rolls off the table (27 ms)

  ● ex4-pokerDiceAll › `rollDice` should not contain unneeded console.log calls

    expect(received).toBe(expected) // Object.is equality

    Expected: false
    Received: true

      137 |       });
      138 |
    > 139 |     expect(callsConsoleLog).toBe(false);
          |                             ^
      140 |   });
      141 | }
      142 |

      at Object.<anonymous> (test-runner/unit-test-helpers.js:139:29)

Test Suites: 1 failed, 1 total
Tests:       1 failed, 6 passed, 7 total
Snapshots:   0 total
Time:        0.234 s, estimated 1 s
Ran all test suites matching /ex4-pokerDiceAll.test.js/i.
2022-02-07 02:47:36 info: --------------------------------------------
2022-02-07 02:47:36 info: >>> Running Unit Test `ex4-pokerDiceAll` <<<
2022-02-07 02:47:36 info: --------------------------------------------
2022-02-07 02:47:37 info: All unit tests passed.
2022-02-07 02:47:38 info: All steps were completed successfully
2022-02-07 08:24:13 info: --------------------------------------------
2022-02-07 08:24:13 info: >>> Running Unit Test `ex4-pokerDiceAll` <<<
2022-02-07 08:24:13 info: --------------------------------------------
2022-02-07 08:24:14 info: All unit tests passed.
2022-02-07 08:24:15 info: All steps were completed successfully
2022-02-07 08:32:12 info: ----------------------------------------------
2022-02-07 08:32:12 info: >>> Running Unit Test `ex5-pokerDiceChain` <<<
2022-02-07 08:32:12 info: ----------------------------------------------
2022-02-07 08:32:13 info: All unit tests passed.
2022-02-07 08:32:14 info: All steps were completed successfully
2022-02-07 08:49:08 info: ----------------------------------------------
2022-02-07 08:49:08 info: >>> Running Unit Test `ex5-pokerDiceChain` <<<
2022-02-07 08:49:08 info: ----------------------------------------------
2022-02-07 08:49:09 info: All unit tests passed.
2022-02-07 08:49:10 info: All steps were completed successfully
2022-02-16 03:33:47 info: ---------------------------------------
2022-02-16 03:33:47 info: >>> Running Unit Test `ex1-johnWho` <<<
2022-02-16 03:33:47 info: ---------------------------------------
2022-02-16 03:33:49 info: All unit tests passed.
2022-02-16 03:33:50 info: All steps were completed successfully
2022-02-16 04:27:01 info: --------------------------------------------
2022-02-16 04:27:01 info: >>> Running Unit Test `ex4-pokerDiceAll` <<<
2022-02-16 04:27:01 info: --------------------------------------------
2022-02-16 04:27:03 info: All unit tests passed.
2022-02-16 04:27:04 info: All steps were completed successfully
